<robot name = "robot">
    <link name="Link0">
        <inertial>
            <origin xyz="-1 0 0.5" rpy="0 0 0"/>
            <mass value="1" />
            <inertia ixx="100" ixy="0" ixz="0" iyy="100" iyz="0" izz="100" />
        </inertial>
        <visual>
            <origin xyz="-1 0 0.5" rpy="0 0 0"/>
            <geometry>
                <box size="1.016313958871695 0.38814045461294244 0.4285205894100186" />
            </geometry>
            <material name="Green">
                <color rgba="0 1.0 0 1.0"/>
            </material>
        </visual>
        <collision>
            <origin xyz="-1 0 0.5" rpy="0 0 0"/>
            <geometry>
                <box size="1.016313958871695 0.38814045461294244 0.4285205894100186" />
            </geometry>
        </collision>
    </link>
    <joint name="Link0_Link1" type="revolute">
       <parent link="Link0"/>
       <child  link="Link1"/>
       <origin rpy="0 0 0" xyz="-1 0 0.7142602947050093" />
     <axis xyz="1 0 0"/>
       <limit effort="0.0" lower="-3.14159" upper="3.14159" velocity="0.0"/>
    </joint>
    <link name="Link1">
        <inertial>
            <origin xyz="0 0 0.4995786869674873" rpy="0 0 0"/>
            <mass value="1" />
            <inertia ixx="100" ixy="0" ixz="0" iyy="100" iyz="0" izz="100" />
        </inertial>
        <visual>
            <origin xyz="0 0 0.4995786869674873" rpy="0 0 0"/>
            <geometry>
                <box size="0.3360608100428363 0.36313055635157665 0.9991573739349746" />
            </geometry>
            <material name="Green">
                <color rgba="0 1.0 0 1.0"/>
            </material>
        </visual>
        <collision>
            <origin xyz="0 0 0.4995786869674873" rpy="0 0 0"/>
            <geometry>
                <box size="0.3360608100428363 0.36313055635157665 0.9991573739349746" />
            </geometry>
        </collision>
    </link>
    <joint name="Link1_Link2" type="revolute">
       <parent link="Link1"/>
       <child  link="Link2"/>
       <origin rpy="0 0 0" xyz="0 0 0.9991573739349746" />
     <axis xyz="1 0 0"/>
       <limit effort="0.0" lower="-3.14159" upper="3.14159" velocity="0.0"/>
    </joint>
    <link name="Link2">
        <inertial>
            <origin xyz="0 0 0.32255113591463236" rpy="0 0 0"/>
            <mass value="1" />
            <inertia ixx="100" ixy="0" ixz="0" iyy="100" iyz="0" izz="100" />
        </inertial>
        <visual>
            <origin xyz="0 0 0.32255113591463236" rpy="0 0 0"/>
            <geometry>
                <box size="0.3749746019982261 0.16152146230112222 0.6451022718292647" />
            </geometry>
            <material name="Green">
                <color rgba="0 1.0 0 1.0"/>
            </material>
        </visual>
        <collision>
            <origin xyz="0 0 0.32255113591463236" rpy="0 0 0"/>
            <geometry>
                <box size="0.3749746019982261 0.16152146230112222 0.6451022718292647" />
            </geometry>
        </collision>
    </link>
</robot>