<robot name = "robot">
    <link name="Link0">
        <inertial>
            <origin xyz="-1 0 0.5" rpy="0 0 0"/>
            <mass value="1" />
            <inertia ixx="100" ixy="0" ixz="0" iyy="100" iyz="0" izz="100" />
        </inertial>
        <visual>
            <origin xyz="-1 0 0.5" rpy="0 0 0"/>
            <geometry>
                <box size="0.7567875956608421 0.7904839759846235 0.8777702020574414" />
            </geometry>
            <material name="Cyan">
                <color rgba="0 1.0 1.0 1.0"/>
            </material>
        </visual>
        <collision>
            <origin xyz="-1 0 0.5" rpy="0 0 0"/>
            <geometry>
                <box size="0.7567875956608421 0.7904839759846235 0.8777702020574414" />
            </geometry>
        </collision>
    </link>
    <joint name="Link0_Link1" type="revolute">
       <parent link="Link0"/>
       <child  link="Link1"/>
       <origin rpy="0 0 0" xyz="-1 -0.39524198799231175 0.5" />
     <axis xyz="1 0 0"/>
       <limit effort="0.0" lower="-3.14159" upper="3.14159" velocity="0.0"/>
    </joint>
    <link name="Link1">
        <inertial>
            <origin xyz="0 0.24076732673173418 0" rpy="0 0 0"/>
            <mass value="1" />
            <inertia ixx="100" ixy="0" ixz="0" iyy="100" iyz="0" izz="100" />
        </inertial>
        <visual>
            <origin xyz="0 0.24076732673173418 0" rpy="0 0 0"/>
            <geometry>
                <box size="0.69758435287211 0.48153465346346835 0.9927620668479925" />
            </geometry>
            <material name="Green">
                <color rgba="0 1.0 0 1.0"/>
            </material>
        </visual>
        <collision>
            <origin xyz="0 0.24076732673173418 0" rpy="0 0 0"/>
            <geometry>
                <box size="0.69758435287211 0.48153465346346835 0.9927620668479925" />
            </geometry>
        </collision>
    </link>
    <joint name="Link1_Link2" type="revolute">
       <parent link="Link1"/>
       <child  link="Link2"/>
       <origin rpy="0 0 0" xyz="0 0.24076732673173418 0.49638103342399625" />
     <axis xyz="1 0 0"/>
       <limit effort="0.0" lower="-3.14159" upper="3.14159" velocity="0.0"/>
    </joint>
    <link name="Link2">
        <inertial>
            <origin xyz="0 0 0.25770739467663073" rpy="0 0 0"/>
            <mass value="1" />
            <inertia ixx="100" ixy="0" ixz="0" iyy="100" iyz="0" izz="100" />
        </inertial>
        <visual>
            <origin xyz="0 0 0.25770739467663073" rpy="0 0 0"/>
            <geometry>
                <box size="0.9319787020349445 0.5037690924897503 0.5154147893532615" />
            </geometry>
            <material name="Cyan">
                <color rgba="0 1.0 1.0 1.0"/>
            </material>
        </visual>
        <collision>
            <origin xyz="0 0 0.25770739467663073" rpy="0 0 0"/>
            <geometry>
                <box size="0.9319787020349445 0.5037690924897503 0.5154147893532615" />
            </geometry>
        </collision>
    </link>
    <joint name="Link2_Link3" type="revolute">
       <parent link="Link2"/>
       <child  link="Link3"/>
       <origin rpy="0 0 0" xyz="0 -0.25188454624487516 0.25770739467663073" />
     <axis xyz="1 0 0"/>
       <limit effort="0.0" lower="-3.14159" upper="3.14159" velocity="0.0"/>
    </joint>
    <link name="Link3">
        <inertial>
            <origin xyz="0 -0.40625154328365964 0" rpy="0 0 0"/>
            <mass value="1" />
            <inertia ixx="100" ixy="0" ixz="0" iyy="100" iyz="0" izz="100" />
        </inertial>
        <visual>
            <origin xyz="0 -0.40625154328365964 0" rpy="0 0 0"/>
            <geometry>
                <box size="1.076838614585976 0.8125030865673193 0.7009912161596294" />
            </geometry>
            <material name="Green">
                <color rgba="0 1.0 0 1.0"/>
            </material>
        </visual>
        <collision>
            <origin xyz="0 -0.40625154328365964 0" rpy="0 0 0"/>
            <geometry>
                <box size="1.076838614585976 0.8125030865673193 0.7009912161596294" />
            </geometry>
        </collision>
    </link>
</robot>