<robot name = "robot">
    <link name="Link0">
        <inertial>
            <origin xyz="-1 0 0.5" rpy="0 0 0"/>
            <mass value="1" />
            <inertia ixx="100" ixy="0" ixz="0" iyy="100" iyz="0" izz="100" />
        </inertial>
        <visual>
            <origin xyz="-1 0 0.5" rpy="0 0 0"/>
            <geometry>
                <box size="0.4046136442022019 0.10845687111744487 0.6369187594616446" />
            </geometry>
            <material name="Green">
                <color rgba="0 1.0 0 1.0"/>
            </material>
        </visual>
        <collision>
            <origin xyz="-1 0 0.5" rpy="0 0 0"/>
            <geometry>
                <box size="0.4046136442022019 0.10845687111744487 0.6369187594616446" />
            </geometry>
        </collision>
    </link>
    <joint name="Link0_Link1" type="revolute">
       <parent link="Link0"/>
       <child  link="Link1"/>
       <origin rpy="0 0 0" xyz="-1.202306822101101 0 0.5" />
     <axis xyz="1 0 0"/>
       <limit effort="0.0" lower="-3.14159" upper="3.14159" velocity="0.0"/>
    </joint>
    <link name="Link1">
        <inertial>
            <origin xyz="-0.10172368941474504 0 0" rpy="0 0 0"/>
            <mass value="1" />
            <inertia ixx="100" ixy="0" ixz="0" iyy="100" iyz="0" izz="100" />
        </inertial>
        <visual>
            <origin xyz="-0.10172368941474504 0 0" rpy="0 0 0"/>
            <geometry>
                <box size="0.20344737882949007 0.5283308451945943 1.0255735536597" />
            </geometry>
            <material name="Cyan">
                <color rgba="0 1.0 1.0 1.0"/>
            </material>
        </visual>
        <collision>
            <origin xyz="-0.10172368941474504 0 0" rpy="0 0 0"/>
            <geometry>
                <box size="0.20344737882949007 0.5283308451945943 1.0255735536597" />
            </geometry>
        </collision>
    </link>
    <joint name="Link1_Link2" type="revolute">
       <parent link="Link1"/>
       <child  link="Link2"/>
       <origin rpy="0 0 0" xyz="-0.20344737882949007 0 0" />
     <axis xyz="1 0 0"/>
       <limit effort="0.0" lower="-3.14159" upper="3.14159" velocity="0.0"/>
    </joint>
    <link name="Link2">
        <inertial>
            <origin xyz="-0.3178637366704662 0 0" rpy="0 0 0"/>
            <mass value="1" />
            <inertia ixx="100" ixy="0" ixz="0" iyy="100" iyz="0" izz="100" />
        </inertial>
        <visual>
            <origin xyz="-0.3178637366704662 0 0" rpy="0 0 0"/>
            <geometry>
                <box size="0.6357274733409324 0.8163668961918894 0.5970091048913732" />
            </geometry>
            <material name="Green">
                <color rgba="0 1.0 0 1.0"/>
            </material>
        </visual>
        <collision>
            <origin xyz="-0.3178637366704662 0 0" rpy="0 0 0"/>
            <geometry>
                <box size="0.6357274733409324 0.8163668961918894 0.5970091048913732" />
            </geometry>
        </collision>
    </link>
    <joint name="Link2_Link3" type="revolute">
       <parent link="Link2"/>
       <child  link="Link3"/>
       <origin rpy="0 0 0" xyz="-0.3178637366704662 -0.4081834480959447 0" />
     <axis xyz="1 0 0"/>
       <limit effort="0.0" lower="-3.14159" upper="3.14159" velocity="0.0"/>
    </joint>
    <link name="Link3">
        <inertial>
            <origin xyz="0 -0.1057165208140954 0" rpy="0 0 0"/>
            <mass value="1" />
            <inertia ixx="100" ixy="0" ixz="0" iyy="100" iyz="0" izz="100" />
        </inertial>
        <visual>
            <origin xyz="0 -0.1057165208140954 0" rpy="0 0 0"/>
            <geometry>
                <box size="0.3342154437150884 0.2114330416281908 0.13656366882747198" />
            </geometry>
            <material name="Cyan">
                <color rgba="0 1.0 1.0 1.0"/>
            </material>
        </visual>
        <collision>
            <origin xyz="0 -0.1057165208140954 0" rpy="0 0 0"/>
            <geometry>
                <box size="0.3342154437150884 0.2114330416281908 0.13656366882747198" />
            </geometry>
        </collision>
    </link>
    <joint name="Link3_Link4" type="revolute">
       <parent link="Link3"/>
       <child  link="Link4"/>
       <origin rpy="0 0 0" xyz="0 -0.2114330416281908 0" />
     <axis xyz="1 0 0"/>
       <limit effort="0.0" lower="-3.14159" upper="3.14159" velocity="0.0"/>
    </joint>
    <link name="Link4">
        <inertial>
            <origin xyz="0 -0.2633744900705872 0" rpy="0 0 0"/>
            <mass value="1" />
            <inertia ixx="100" ixy="0" ixz="0" iyy="100" iyz="0" izz="100" />
        </inertial>
        <visual>
            <origin xyz="0 -0.2633744900705872 0" rpy="0 0 0"/>
            <geometry>
                <box size="0.2928513107024494 0.5267489801411744 0.41341599658661543" />
            </geometry>
            <material name="Cyan">
                <color rgba="0 1.0 1.0 1.0"/>
            </material>
        </visual>
        <collision>
            <origin xyz="0 -0.2633744900705872 0" rpy="0 0 0"/>
            <geometry>
                <box size="0.2928513107024494 0.5267489801411744 0.41341599658661543" />
            </geometry>
        </collision>
    </link>
    <joint name="Link4_Link5" type="revolute">
       <parent link="Link4"/>
       <child  link="Link5"/>
       <origin rpy="0 0 0" xyz="-0.1464256553512247 -0.2633744900705872 0" />
     <axis xyz="1 0 0"/>
       <limit effort="0.0" lower="-3.14159" upper="3.14159" velocity="0.0"/>
    </joint>
    <link name="Link5">
        <inertial>
            <origin xyz="-0.11155739890160622 0 0" rpy="0 0 0"/>
            <mass value="1" />
            <inertia ixx="100" ixy="0" ixz="0" iyy="100" iyz="0" izz="100" />
        </inertial>
        <visual>
            <origin xyz="-0.11155739890160622 0 0" rpy="0 0 0"/>
            <geometry>
                <box size="0.22311479780321244 0.26813594270941266 0.13371712088203072" />
            </geometry>
            <material name="Green">
                <color rgba="0 1.0 0 1.0"/>
            </material>
        </visual>
        <collision>
            <origin xyz="-0.11155739890160622 0 0" rpy="0 0 0"/>
            <geometry>
                <box size="0.22311479780321244 0.26813594270941266 0.13371712088203072" />
            </geometry>
        </collision>
    </link>
</robot>