<robot name = "robot">
    <link name="Link0">
        <inertial>
            <origin xyz="-1 0 0.5" rpy="0 0 0"/>
            <mass value="1" />
            <inertia ixx="100" ixy="0" ixz="0" iyy="100" iyz="0" izz="100" />
        </inertial>
        <visual>
            <origin xyz="-1 0 0.5" rpy="0 0 0"/>
            <geometry>
                <box size="0.7889843358907684 0.9199373193074633 0.3644634609823113" />
            </geometry>
            <material name="Green">
                <color rgba="0 1.0 0 1.0"/>
            </material>
        </visual>
        <collision>
            <origin xyz="-1 0 0.5" rpy="0 0 0"/>
            <geometry>
                <box size="0.7889843358907684 0.9199373193074633 0.3644634609823113" />
            </geometry>
        </collision>
    </link>
    <joint name="Link0_Link1" type="revolute">
       <parent link="Link0"/>
       <child  link="Link1"/>
       <origin rpy="0 0 0" xyz="-1.3944921679453843 0 0.5" />
     <axis xyz="1 0 0"/>
       <limit effort="0.0" lower="-3.14159" upper="3.14159" velocity="0.0"/>
    </joint>
    <link name="Link1">
        <inertial>
            <origin xyz="-0.4047045925979803 0 0" rpy="0 0 0"/>
            <mass value="1" />
            <inertia ixx="100" ixy="0" ixz="0" iyy="100" iyz="0" izz="100" />
        </inertial>
        <visual>
            <origin xyz="-0.4047045925979803 0 0" rpy="0 0 0"/>
            <geometry>
                <box size="0.8094091851959606 0.713867253121178 0.9731190946123245" />
            </geometry>
            <material name="Cyan">
                <color rgba="0 1.0 1.0 1.0"/>
            </material>
        </visual>
        <collision>
            <origin xyz="-0.4047045925979803 0 0" rpy="0 0 0"/>
            <geometry>
                <box size="0.8094091851959606 0.713867253121178 0.9731190946123245" />
            </geometry>
        </collision>
    </link>
    <joint name="Link1_Link2" type="revolute">
       <parent link="Link1"/>
       <child  link="Link2"/>
       <origin rpy="0 0 0" xyz="-0.8094091851959606 0 0" />
     <axis xyz="1 0 0"/>
       <limit effort="0.0" lower="-3.14159" upper="3.14159" velocity="0.0"/>
    </joint>
    <link name="Link2">
        <inertial>
            <origin xyz="-0.21700896652753404 0 0" rpy="0 0 0"/>
            <mass value="1" />
            <inertia ixx="100" ixy="0" ixz="0" iyy="100" iyz="0" izz="100" />
        </inertial>
        <visual>
            <origin xyz="-0.21700896652753404 0 0" rpy="0 0 0"/>
            <geometry>
                <box size="0.4340179330550681 1.0131299905702147 0.5291731749549323" />
            </geometry>
            <material name="Green">
                <color rgba="0 1.0 0 1.0"/>
            </material>
        </visual>
        <collision>
            <origin xyz="-0.21700896652753404 0 0" rpy="0 0 0"/>
            <geometry>
                <box size="0.4340179330550681 1.0131299905702147 0.5291731749549323" />
            </geometry>
        </collision>
    </link>
    <joint name="Link2_Link3" type="revolute">
       <parent link="Link2"/>
       <child  link="Link3"/>
       <origin rpy="0 0 0" xyz="-0.21700896652753404 -0.5065649952851073 0" />
     <axis xyz="1 0 0"/>
       <limit effort="0.0" lower="-3.14159" upper="3.14159" velocity="0.0"/>
    </joint>
    <link name="Link3">
        <inertial>
            <origin xyz="0 -0.2270193508661243 0" rpy="0 0 0"/>
            <mass value="1" />
            <inertia ixx="100" ixy="0" ixz="0" iyy="100" iyz="0" izz="100" />
        </inertial>
        <visual>
            <origin xyz="0 -0.2270193508661243 0" rpy="0 0 0"/>
            <geometry>
                <box size="0.43698954963064784 0.4540387017322486 0.37265509757948134" />
            </geometry>
            <material name="Cyan">
                <color rgba="0 1.0 1.0 1.0"/>
            </material>
        </visual>
        <collision>
            <origin xyz="0 -0.2270193508661243 0" rpy="0 0 0"/>
            <geometry>
                <box size="0.43698954963064784 0.4540387017322486 0.37265509757948134" />
            </geometry>
        </collision>
    </link>
    <joint name="Link3_Link4" type="revolute">
       <parent link="Link3"/>
       <child  link="Link4"/>
       <origin rpy="0 0 0" xyz="0 -0.4540387017322486 0" />
     <axis xyz="1 0 0"/>
       <limit effort="0.0" lower="-3.14159" upper="3.14159" velocity="0.0"/>
    </joint>
    <link name="Link4">
        <inertial>
            <origin xyz="0 -0.5383007235815406 0" rpy="0 0 0"/>
            <mass value="1" />
            <inertia ixx="100" ixy="0" ixz="0" iyy="100" iyz="0" izz="100" />
        </inertial>
        <visual>
            <origin xyz="0 -0.5383007235815406 0" rpy="0 0 0"/>
            <geometry>
                <box size="0.7454736115807171 1.0766014471630811 0.2242182016236536" />
            </geometry>
            <material name="Cyan">
                <color rgba="0 1.0 1.0 1.0"/>
            </material>
        </visual>
        <collision>
            <origin xyz="0 -0.5383007235815406 0" rpy="0 0 0"/>
            <geometry>
                <box size="0.7454736115807171 1.0766014471630811 0.2242182016236536" />
            </geometry>
        </collision>
    </link>
    <joint name="Link4_Link5" type="revolute">
       <parent link="Link4"/>
       <child  link="Link5"/>
       <origin rpy="0 0 0" xyz="0 -1.0766014471630811 0" />
     <axis xyz="1 0 0"/>
       <limit effort="0.0" lower="-3.14159" upper="3.14159" velocity="0.0"/>
    </joint>
    <link name="Link5">
        <inertial>
            <origin xyz="0 -0.21027967439415418 0" rpy="0 0 0"/>
            <mass value="1" />
            <inertia ixx="100" ixy="0" ixz="0" iyy="100" iyz="0" izz="100" />
        </inertial>
        <visual>
            <origin xyz="0 -0.21027967439415418 0" rpy="0 0 0"/>
            <geometry>
                <box size="0.14533609543921713 0.42055934878830836 0.965766668063065" />
            </geometry>
            <material name="Cyan">
                <color rgba="0 1.0 1.0 1.0"/>
            </material>
        </visual>
        <collision>
            <origin xyz="0 -0.21027967439415418 0" rpy="0 0 0"/>
            <geometry>
                <box size="0.14533609543921713 0.42055934878830836 0.965766668063065" />
            </geometry>
        </collision>
    </link>
    <joint name="Link5_Link6" type="revolute">
       <parent link="Link5"/>
       <child  link="Link6"/>
       <origin rpy="0 0 0" xyz="0 -0.42055934878830836 0" />
     <axis xyz="1 0 0"/>
       <limit effort="0.0" lower="-3.14159" upper="3.14159" velocity="0.0"/>
    </joint>
    <link name="Link6">
        <inertial>
            <origin xyz="0 -0.3969353305131943 0" rpy="0 0 0"/>
            <mass value="1" />
            <inertia ixx="100" ixy="0" ixz="0" iyy="100" iyz="0" izz="100" />
        </inertial>
        <visual>
            <origin xyz="0 -0.3969353305131943 0" rpy="0 0 0"/>
            <geometry>
                <box size="1.0942271222828088 0.7938706610263886 0.6506209192092642" />
            </geometry>
            <material name="Cyan">
                <color rgba="0 1.0 1.0 1.0"/>
            </material>
        </visual>
        <collision>
            <origin xyz="0 -0.3969353305131943 0" rpy="0 0 0"/>
            <geometry>
                <box size="1.0942271222828088 0.7938706610263886 0.6506209192092642" />
            </geometry>
        </collision>
    </link>
    <joint name="Link6_Link7" type="revolute">
       <parent link="Link6"/>
       <child  link="Link7"/>
       <origin rpy="0 0 0" xyz="0 -0.3969353305131943 0.3253104596046321" />
     <axis xyz="1 0 0"/>
       <limit effort="0.0" lower="-3.14159" upper="3.14159" velocity="0.0"/>
    </joint>
    <link name="Link7">
        <inertial>
            <origin xyz="0 0 0.2554942257695208" rpy="0 0 0"/>
            <mass value="1" />
            <inertia ixx="100" ixy="0" ixz="0" iyy="100" iyz="0" izz="100" />
        </inertial>
        <visual>
            <origin xyz="0 0 0.2554942257695208" rpy="0 0 0"/>
            <geometry>
                <box size="0.5300133907926274 0.28995836356363314 0.5109884515390416" />
            </geometry>
            <material name="Cyan">
                <color rgba="0 1.0 1.0 1.0"/>
            </material>
        </visual>
        <collision>
            <origin xyz="0 0 0.2554942257695208" rpy="0 0 0"/>
            <geometry>
                <box size="0.5300133907926274 0.28995836356363314 0.5109884515390416" />
            </geometry>
        </collision>
    </link>
    <joint name="Link7_Link8" type="revolute">
       <parent link="Link7"/>
       <child  link="Link8"/>
       <origin rpy="0 0 0" xyz="-0.2650066953963137 0 0.2554942257695208" />
     <axis xyz="1 0 0"/>
       <limit effort="0.0" lower="-3.14159" upper="3.14159" velocity="0.0"/>
    </joint>
    <link name="Link8">
        <inertial>
            <origin xyz="-0.1952665380492783 0 0" rpy="0 0 0"/>
            <mass value="1" />
            <inertia ixx="100" ixy="0" ixz="0" iyy="100" iyz="0" izz="100" />
        </inertial>
        <visual>
            <origin xyz="-0.1952665380492783 0 0" rpy="0 0 0"/>
            <geometry>
                <box size="0.3905330760985566 0.7046990383631423 0.8884418731176029" />
            </geometry>
            <material name="Green">
                <color rgba="0 1.0 0 1.0"/>
            </material>
        </visual>
        <collision>
            <origin xyz="-0.1952665380492783 0 0" rpy="0 0 0"/>
            <geometry>
                <box size="0.3905330760985566 0.7046990383631423 0.8884418731176029" />
            </geometry>
        </collision>
    </link>
</robot>