<robot name = "robot">
    <link name="Link0">
        <inertial>
            <origin xyz="-1 0 0.5" rpy="0 0 0"/>
            <mass value="1" />
            <inertia ixx="100" ixy="0" ixz="0" iyy="100" iyz="0" izz="100" />
        </inertial>
        <visual>
            <origin xyz="-1 0 0.5" rpy="0 0 0"/>
            <geometry>
                <box size="0.5608230790448424 0.5513393532565491 0.4926125090983574" />
            </geometry>
            <material name="Green">
                <color rgba="0 1.0 0 1.0"/>
            </material>
        </visual>
        <collision>
            <origin xyz="-1 0 0.5" rpy="0 0 0"/>
            <geometry>
                <box size="0.5608230790448424 0.5513393532565491 0.4926125090983574" />
            </geometry>
        </collision>
    </link>
    <joint name="Link0_Link1" type="revolute">
       <parent link="Link0"/>
       <child  link="Link1"/>
       <origin rpy="0 0 0" xyz="-1 0 0.7463062545491788" />
     <axis xyz="1 0 0"/>
       <limit effort="0.0" lower="-3.14159" upper="3.14159" velocity="0.0"/>
    </joint>
    <link name="Link1">
        <inertial>
            <origin xyz="0 0 0.25270429340744455" rpy="0 0 0"/>
            <mass value="1" />
            <inertia ixx="100" ixy="0" ixz="0" iyy="100" iyz="0" izz="100" />
        </inertial>
        <visual>
            <origin xyz="0 0 0.25270429340744455" rpy="0 0 0"/>
            <geometry>
                <box size="0.3216119357200712 0.6810006571271021 0.5054085868148891" />
            </geometry>
            <material name="Cyan">
                <color rgba="0 1.0 1.0 1.0"/>
            </material>
        </visual>
        <collision>
            <origin xyz="0 0 0.25270429340744455" rpy="0 0 0"/>
            <geometry>
                <box size="0.3216119357200712 0.6810006571271021 0.5054085868148891" />
            </geometry>
        </collision>
    </link>
    <joint name="Link1_Link2" type="revolute">
       <parent link="Link1"/>
       <child  link="Link2"/>
       <origin rpy="0 0 0" xyz="0.1608059678600356 0 0.25270429340744455" />
     <axis xyz="1 0 0"/>
       <limit effort="0.0" lower="-3.14159" upper="3.14159" velocity="0.0"/>
    </joint>
    <link name="Link2">
        <inertial>
            <origin xyz="0.32654676743438815 0 0" rpy="0 0 0"/>
            <mass value="1" />
            <inertia ixx="100" ixy="0" ixz="0" iyy="100" iyz="0" izz="100" />
        </inertial>
        <visual>
            <origin xyz="0.32654676743438815 0 0" rpy="0 0 0"/>
            <geometry>
                <box size="0.6530935348687763 0.6712141361096572 0.9338938309916567" />
            </geometry>
            <material name="Cyan">
                <color rgba="0 1.0 1.0 1.0"/>
            </material>
        </visual>
        <collision>
            <origin xyz="0.32654676743438815 0 0" rpy="0 0 0"/>
            <geometry>
                <box size="0.6530935348687763 0.6712141361096572 0.9338938309916567" />
            </geometry>
        </collision>
    </link>
    <joint name="Link2_Link3" type="revolute">
       <parent link="Link2"/>
       <child  link="Link3"/>
       <origin rpy="0 0 0" xyz="0.32654676743438815 0.3356070680548286 0" />
     <axis xyz="1 0 0"/>
       <limit effort="0.0" lower="-3.14159" upper="3.14159" velocity="0.0"/>
    </joint>
    <link name="Link3">
        <inertial>
            <origin xyz="0 0.3341034148458679 0" rpy="0 0 0"/>
            <mass value="1" />
            <inertia ixx="100" ixy="0" ixz="0" iyy="100" iyz="0" izz="100" />
        </inertial>
        <visual>
            <origin xyz="0 0.3341034148458679 0" rpy="0 0 0"/>
            <geometry>
                <box size="0.9046976371116172 0.6682068296917358 0.3952897315582309" />
            </geometry>
            <material name="Green">
                <color rgba="0 1.0 0 1.0"/>
            </material>
        </visual>
        <collision>
            <origin xyz="0 0.3341034148458679 0" rpy="0 0 0"/>
            <geometry>
                <box size="0.9046976371116172 0.6682068296917358 0.3952897315582309" />
            </geometry>
        </collision>
    </link>
    <joint name="Link3_Link4" type="revolute">
       <parent link="Link3"/>
       <child  link="Link4"/>
       <origin rpy="0 0 0" xyz="0 0.6682068296917358 0" />
     <axis xyz="1 0 0"/>
       <limit effort="0.0" lower="-3.14159" upper="3.14159" velocity="0.0"/>
    </joint>
    <link name="Link4">
        <inertial>
            <origin xyz="0 0.18504266305814437 0" rpy="0 0 0"/>
            <mass value="1" />
            <inertia ixx="100" ixy="0" ixz="0" iyy="100" iyz="0" izz="100" />
        </inertial>
        <visual>
            <origin xyz="0 0.18504266305814437 0" rpy="0 0 0"/>
            <geometry>
                <box size="0.6246939684303205 0.37008532611628875 0.5229697519532838" />
            </geometry>
            <material name="Green">
                <color rgba="0 1.0 0 1.0"/>
            </material>
        </visual>
        <collision>
            <origin xyz="0 0.18504266305814437 0" rpy="0 0 0"/>
            <geometry>
                <box size="0.6246939684303205 0.37008532611628875 0.5229697519532838" />
            </geometry>
        </collision>
    </link>
    <joint name="Link4_Link5" type="revolute">
       <parent link="Link4"/>
       <child  link="Link5"/>
       <origin rpy="0 0 0" xyz="-0.3123469842151603 0.18504266305814437 0" />
     <axis xyz="1 0 0"/>
       <limit effort="0.0" lower="-3.14159" upper="3.14159" velocity="0.0"/>
    </joint>
    <link name="Link5">
        <inertial>
            <origin xyz="-0.12342880858737233 0 0" rpy="0 0 0"/>
            <mass value="1" />
            <inertia ixx="100" ixy="0" ixz="0" iyy="100" iyz="0" izz="100" />
        </inertial>
        <visual>
            <origin xyz="-0.12342880858737233 0 0" rpy="0 0 0"/>
            <geometry>
                <box size="0.24685761717474466 0.9817298170526354 0.5397047682205176" />
            </geometry>
            <material name="Cyan">
                <color rgba="0 1.0 1.0 1.0"/>
            </material>
        </visual>
        <collision>
            <origin xyz="-0.12342880858737233 0 0" rpy="0 0 0"/>
            <geometry>
                <box size="0.24685761717474466 0.9817298170526354 0.5397047682205176" />
            </geometry>
        </collision>
    </link>
</robot>